Workbook

Sheet Transaksi
A1: Tanggal | B1: Pembeli | C1: Gas Keluar | D1: Omzet | E1: Modal | F1: Laba | G1: Status | H1: Total Piutang | I1: Total Omzet | J1: Total Laba | K1: Sisa Tabung
A2: 46117 | B2: Tate | C2: 2 | D2: =C2*25000 -> 50000 | E2: =C2*'Stok Gas'!$C$2 -> 42000 | F2: =D2-E2 -> 8000 | G2: Lunas | H2: =SUMIF(G:G,"Belum lunas",D:D) -> 225000 | I2: =SUM(D:D) -> 7500000 | J2: =SUM(F:F) -> 1200000 | K2: =SUM('Stok Gas'!B:B)-SUM(C:C) -> 17
A3: 46117 | B3: Kru | C3: 2 | D3: =C3*25000 -> 50000 | E3: =C3*'Stok Gas'!$C$2 -> 42000 | F3: =D3-E3 -> 8000 | G3: Lunas
A4: 46120 | B4: Kru | C4: 5 | D4: =C4*25000 -> 125000 | E4: =C4*'Stok Gas'!$C$2 -> 105000 | F4: =D4-E4 -> 20000 | G4: Lunas
A5: 46120 | B5: RM | C5: 10 | D5: =C5*25000 -> 250000 | E5: =C5*'Stok Gas'!$C$2 -> 210000 | F5: =D5-E5 -> 40000 | G5: Lunas
A6: 46122 | B6: RM | C6: 7 | D6: =C6*25000 -> 175000 | E6: =C6*'Stok Gas'!$C$2 -> 147000 | F6: =D6-E6 -> 28000 | G6: Lunas
A7: 46124 | B7: Wa Iim | C7: 1 | D7: =C7*25000 -> 25000 | E7: =C7*'Stok Gas'!$C$2 -> 21000 | F7: =D7-E7 -> 4000 | G7: Lunas
A8: 46124 | B8: Kru | C8: 2 | D8: =C8*25000 -> 50000 | E8: =C8*'Stok Gas'!$C$2 -> 42000 | F8: =D8-E8 -> 8000 | G8: Lunas
A9: 46124 | B9: Warung Umi | C9: 1 | D9: =C9*25000 -> 25000 | E9: =C9*'Stok Gas'!$C$2 -> 21000 | F9: =D9-E9 -> 4000 | G9: Lunas
A10: 46125 | B10: Tate | C10: 2 | D10: =C10*25000 -> 50000 | E10: =C10*'Stok Gas'!$C$2 -> 42000 | F10: =D10-E10 -> 8000 | G10: Lunas
A11: 46126 | B11: Wa Iim | C11: 2 | D11: =C11*25000 -> 50000 | E11: =C11*'Stok Gas'!$C$2 -> 42000 | F11: =D11-E11 -> 8000 | G11: Lunas
A12: 46126 | B12: Kru | C12: 2 | D12: =C12*25000 -> 50000 | E12: =C12*'Stok Gas'!$C$2 -> 42000 | F12: =D12-E12 -> 8000 | G12: Lunas
A13: 46126 | B13: RM | C13: 4 | D13: =C13*25000 -> 100000 | E13: =C13*'Stok Gas'!$C$2 -> 84000 | F13: =D13-E13 -> 16000 | G13: Lunas
A14: 46126 | B14: Mamat | C14: 5 | D14: =C14*25000 -> 125000 | E14: =C14*'Stok Gas'!$C$2 -> 105000 | F14: =D14-E14 -> 20000 | G14: Lunas
... A16: 46127 | B16: Mamat | C16: 7 | D16: =C16*25000 -> 175000 | E16: =C16*'Stok Gas'!$C$2 -> 147000 | F16: =D16-E16 -> 28000 | G16: Lunas
A17: 46128 | B17: Mamat | C17: =4+2 -> 6 | D17: =C17*25000 -> 150000 | E17: =C17*'Stok Gas'!$C$2 -> 126000 | F17: =D17-E17 -> 24000 | G17: Lunas
A18: 46129 | B18: RM Umi | C18: 4 | D18: =C18*25000 -> 100000 | E18: =C18*'Stok Gas'!$C$2 -> 84000 | F18: =D18-E18 -> 16000 | G18: Lunas
A19: 46129 | B19: Kru | C19: 2 | D19: =C19*25000 -> 50000 | E19: =C19*'Stok Gas'!$C$2 -> 42000 | F19: =D19-E19 -> 8000 | G19: Lunas
A20: 46130 | B20: Kru | C20: 1 | D20: =C20*25000 -> 25000 | E20: =C20*'Stok Gas'!$C$2 -> 21000 | F20: =D20-E20 -> 4000 | G20: Lunas
A21: 46130 | B21: Mamat | C21: 4 | D21: =C21*25000 -> 100000 | E21: =C21*'Stok Gas'!$C$2 -> 84000 | F21: =D21-E21 -> 16000 | G21: Lunas
A22: 46131 | B22: Mamat | C22: 4 | D22: =C22*25000 -> 100000 | E22: =C22*'Stok Gas'!$C$2 -> 84000 | F22: =D22-E22 -> 16000 | G22: Lunas
A23: 46131 | B23: Kru | C23: 2 | D23: =C23*25000 -> 50000 | E23: =C23*'Stok Gas'!$C$2 -> 42000 | F23: =D23-E23 -> 8000 | G23: Lunas
A24: 46131 | B24: Tate | C24: 2 | D24: =C24*25000 -> 50000 | E24: =C24*'Stok Gas'!$C$2 -> 42000 | F24: =D24-E24 -> 8000 | G24: Lunas
A25: 46131 | B25: Mamat | C25: 4 | D25: =C25*25000 -> 100000 | E25: =C25*'Stok Gas'!$C$2 -> 84000 | F25: =D25-E25 -> 16000 | G25: Lunas
A26: 46132 | B26: kru | C26: 2 | D26: =C26*25000 -> 50000 | E26: =C26*'Stok Gas'!$C$2 -> 42000 | F26: =D26-E26 -> 8000 | G26: Lunas
A27: 46132 | B27: Wa Iim | C27: 1 | D27: =C27*25000 -> 25000 | E27: =C27*'Stok Gas'!$C$2 -> 21000 | F27: =D27-E27 -> 4000 | G27: Lunas
A28: 46133 | B28: Mamat | C28: 8 | D28: =C28*25000 -> 200000 | E28: =C28*'Stok Gas'!$C$2 -> 168000 | F28: =D28-E28 -> 32000 | G28: Lunas
A29: 46133 | B29: Kru | C29: 2 | D29: =C29*25000 -> 50000 | E29: =C29*'Stok Gas'!$C$2 -> 42000 | F29: =D29-E29 -> 8000 | G29: Lunas
... A107: 46176 | B107: Kru | C107: 1 | D107: =C107*25000 -> 25000 | E107: =C107*'Stok Gas'!$C$2 -> 21000 | F107: =D107-E107 -> 4000 | G107: Belum lunas
D108: =C108*25000 -> 0 | E108: =C108*'Stok Gas'!$C$2 -> 0 | F108: =D108-E108 -> 0 | G108: Belum lunas
D109: =C109*25000 -> 0 | E109: =C109*'Stok Gas'!$C$2 -> 0 | F109: =D109-E109 -> 0 | G109: Belum lunas
D110: =C110*25000 -> 0 | E110: =C110*'Stok Gas'!$C$2 -> 0 | F110: =D110-E110 -> 0 | G110: Belum lunas
D111: =C111*25000 -> 0 | E111: =C111*'Stok Gas'!$C$2 -> 0 | F111: =D111-E111 -> 0 | G111: Belum lunas
D112: =C112*25000 -> 0 | E112: =C112*'Stok Gas'!$C$2 -> 0 | F112: =D112-E112 -> 0 | G112: Belum lunas
D113: =C113*25000 -> 0 | E113: =C113*'Stok Gas'!$C$2 -> 0 | F113: =D113-E113 -> 0 | G113: Belum lunas
D114: =C114*25000 -> 0 | E114: =C114*'Stok Gas'!$C$2 -> 0 | F114: =D114-E114 -> 0 | G114: Belum lunas
D115: =C115*25000 -> 0 | E115: =C115*'Stok Gas'!$C$2 -> 0 | F115: =D115-E115 -> 0 | G115: Belum lunas
D116: =C116*25000 -> 0 | E116: =C116*'Stok Gas'!$C$2 -> 0 | F116: =D116-E116 -> 0 | G116: Belum lunas
D117: =C117*25000 -> 0 | E117: =C117*'Stok Gas'!$C$2 -> 0 | F117: =D117-E117 -> 0 | G117: Belum lunas
D118: =C118*25000 -> 0 | E118: =C118*'Stok Gas'!$C$2 -> 0 | F118: =D118-E118 -> 0 | G118: Belum lunas
...

Sheet Dashboard

Sheet Stok Gas
A1: Tanggal | B1: Tabung Masuk | C1: Modal Satuan | D1: Total Modal | E1: Sisa Tabung
A2: 46116 | B2: 30 | C2: 21000 | D2: =C2*B2 -> 630000 | E2: =Transaksi!K2 -> 17
A3: 46125 | B3: 28 | C3: 21000 | D3: =C3*B3 -> 588000
A4: 46128 | B4: 26 | C4: 21000 | D4: =C4*B4 -> 546000
A5: 46131 | B5: 25 | C5: 21000 | D5: =C5*B5 -> 525000
A6: 46135 | B6: 24 | C6: 21000 | D6: =C6*B6 -> 504000
A7: 46141 | B7: 28 | C7: 21000 | D7: =C7*B7 -> 588000
A8: 46145 | B8: 24 | C8: 21000 | D8: =C8*B8 -> 504000
A9: 46149 | B9: 26 | C9: 21000 | D9: =C9*B9 -> 546000
A10: 46155 | B10: 25 | C10: 21000 | D10: =C10*B10 -> 525000
A11: 46160 | B11: 25 | C11: 21000 | D11: =C11*B11 -> 525000
A12: 46163 | B12: 27 | C12: 21000 | D12: =C12*B12 -> 567000
A13: 46172 | B13: 29 | C13: 21000 | D13: =C13*B13 -> 609000
C14: 21000 | D14: =C14*B14 -> 0
C15: 21000 | D15: =C15*B15 -> 0
C16: 21000 | D16: =C16*B16 -> 0
C17: 21000 | D17: =C17*B17 -> 0
C18: 21000 | D18: =C18*B18 -> 0
C19: 21000 | D19: =C19*B19 -> 0
C20: 21000 | D20: =C20*B20 -> 0
C21: 21000 | D21: =C21*B21 -> 0
C22: 21000 | D22: =C22*B22 -> 0
C23: 21000 | D23: =C23*B23 -> 0
C24: 21000 | D24: =C24*B24 -> 0
C25: 21000 | D25: =C25*B25 -> 0
... C31: 21000 | D31: =C31*B31 -> 0

Sheet Piutang
A1: PIUTANG
A2: Nama | B2: April | C2: Mei | D2: Juni | E2: Jml tabung | F2: Total
A3: Mamat | B3: =SUMIFS(Transaksi!D:D,Transaksi!B:B,"Mamat",Transaksi!G:G,"Belum lunas",Transaksi!A:A,">="&DATE(2026,4,1),Transaksi!A:A,"<"&DATE(2026,5,1)) -> 0 | C3: =SUMIFS(Transaksi!D:D,Transaksi!B:B,"Mamat",Transaksi!G:G,"Belum lunas",Transaksi!A:A,">="&DATE(2026,5,1),Transaksi!A:A,"<"&DATE(2026,6,1)) -> 50000 | D3: =SUMIFS(Transaksi!D:D,Transaksi!B:B,"Mamat",Transaksi!G:G,"Belum lunas",Transaksi!A:A,">="&DATE(2026,6,1),Transaksi!A:A,"<"&DATE(2026,7,1)) -> 0 | E3: =SUMIFS(Transaksi!C:C,Transaksi!B:B,"Mamat",Transaksi!G:G,"Belum lunas") -> 2 | F3: =SUM(B3:C3) -> 50000
A4: Kru | B4: =SUMIFS(Transaksi!D:D,Transaksi!B:B,"Kru",Transaksi!G:G,"Belum lunas",Transaksi!A:A,">="&DATE(2026,4,1),Transaksi!A:A,"<"&DATE(2026,5,1)) -> 0 | C4: =SUMIFS(Transaksi!D:D,Transaksi!B:B,"Kru",Transaksi!G:G,"Belum lunas",Transaksi!A:A,">="&DATE(2026,5,1),Transaksi!A:A,"<"&DATE(2026,6,1)) -> 150000 | D4: =SUMIFS(Transaksi!D:D,Transaksi!B:B,"Kru",Transaksi!G:G,"Belum lunas",Transaksi!A:A,">="&DATE(2026,6,1),Transaksi!A:A,"<"&DATE(2026,7,1)) -> 25000 | E4: =SUMIFS(Transaksi!C:C,Transaksi!B:B,"Kru",Transaksi!G:G,"Belum lunas") -> 7 | F4: =SUM(B4:C4) -> 150000
